Workbook
Name \a: #REF!
Name \c: #N/A
Name \NvsElapsedTime: 0.000203356481506489
Name \NvsEndTime: 37484.6666479167
Name \nvsinstspec: "%,FDEPTID,V121"
Name \nvspaneleffdt: "V2002-05-01"
Name \nvstreeasd: "V2002-07-31"
Name \o: #N/A
Name \p: #N/A
Name \r: #N/A
Name \t: #N/A
Name \X: #REF!
Name \y: #N/A
Name \z: #N/A
Name _.ignore9._: #REF!
Name _?: #REF!
Name _????: #REF!
Name _?????????: #REF!
Name _??_???: #REF!
Name _?_??: #REF!
Name ____________________________________________________________________________________________________FEB1: #N/A
Name ____________________________________________________________________________________________________FEB2: #N/A
Name ___________________________________________________________________________________________________FEB1: #N/A
Name ___________________________________________________________________________________________________FEB2: #N/A
Name _________________________________________________________________________________________________FEB1: #N/A
Name _________________________________________________________________________________________________FEB2: #N/A
Name _________________________________________________________________________________________________m21: #N/A
Name ________________________________________________________________________________________________FEB1: #N/A
Name ________________________________________________________________________________________________FEB2: #N/A
Name ________________________________________________________________________________________________m21: #N/A
Name _______________________________________________________________________________________________FEB1: #N/A
Name _______________________________________________________________________________________________FEB2: #N/A
Name _______________________________________________________________________________________________m21: #N/A
Name ______________________________________________________________________________________________m21: #N/A
Name _____________________________________________________________________________________________FEB1: #N/A
Name _____________________________________________________________________________________________FEB2: #N/A
Name ____________________________________________________________________________________________m21: #N/A
Name ___________________________________________________________________________________________FEB1: #N/A
Name ___________________________________________________________________________________________FEB2: #N/A
Name __________________________________________________________________________________________m21: #N/A
Name _________________________________________________________________________________________FEB1: #N/A
Name _________________________________________________________________________________________FEB2: #N/A
Name ________________________________________________________________________________________FEB1: #N/A
Name ________________________________________________________________________________________FEB2: #N/A
Name ________________________________________________________________________________________m21: #N/A
Name _______________________________________________________________________________________FEB1: #N/A
Name _______________________________________________________________________________________FEB2: #N/A
Name _______________________________________________________________________________________m21: #N/A
Name ______________________________________________________________________________________FEB1: #N/A
Name ______________________________________________________________________________________FEB2: #N/A
Name ______________________________________________________________________________________m21: #N/A
Name _____________________________________________________________________________________FEB1: #N/A
Name _____________________________________________________________________________________FEB2: #N/A
Name _____________________________________________________________________________________m21: #N/A
Name ____________________________________________________________________________________FEB1: #N/A
Name ____________________________________________________________________________________FEB2: #N/A
Name ____________________________________________________________________________________m21: #N/A
Name ___________________________________________________________________________________FEB1: #N/A
Name ___________________________________________________________________________________FEB2: #N/A
Name ___________________________________________________________________________________m21: #N/A

Sheet Industry Growth
A2: xx | B2: General Insurance Industry Growth (INR cr)
B3: Segments | C3: 15 | D3: =C3+1 | E3: =D3+1 | F3: =E3+1 | G3: =F3+1 | H3: =G3+1 | I3: =H3+1 | J3: =I3+1 | K3: =J3+1 | ... N3: =M3+1 | O3: FY23 Mix % | P3: FY26 Mix % | Q3: YoY growth | R3: CAGR (FY23-26) | T3: Key observations - General Insurance
B4: Health Insurance | C4: 20615 | D4: 25037 | E4: 31164 | F4: 37711.79 | G4: 45488.91 | H4: 51674.49 | I4: 58572.46 | J4: 73598.14 | K4: 90651.64 | L4: 108911.39 | M4: 118687.94 | N4: 137144.46 | O4: =K4/K$7 | P4: =N4/N$7 | Q4: =N4/M4-1 | R4: =(N4/K4)^(1/3)-1 | T4: 1. General Insurance industry has grown by 9.3% in FY26 (compared to ~6.2% in FY25)
B5: Motor Insurance | C5: =20755+18006 | D5: =22731+21293 | E5: =25160+26649 | F5: 59247.97 | G5: 64454.86 | H5: 68950.93 | I5: 67790.01 | J5: 70433.48 | K5: 81280.031 | L5: 91780.53 | M5: 99065.82 | N5: 108216.08 | O5: =K5/K$7 | P5: =N5/N$7 | Q5: =N5/M5-1 | R5: =(N5/K5)^(1/3)-1 | T5: 2. 2y CAGR for Health insurance segment is at 14.8% even after 1/n which impacted FY25
B6: Others | C6: =C7-SUM(C4:C5) | D6: =D7-SUM(D4:D5) | E6: =E7-SUM(E4:E5) | F6: =F7-SUM(F4:F5) | G6: =G7-SUM(G4:G5) | H6: =H7-SUM(H4:H5) | I6: =I7-SUM(I4:I5) | J6: =J7-SUM(J4:J5) | ... N6: =N7-SUM(N4:N5) | O6: =K6/K$7 | P6: =N6/N$7 | Q6: =N6/M6-1 | R6: =(N6/K6)^(1/3)-1
B7: Total | C7: 90365 | D7: 102396 | E7: 134177 | F7: 150592.78 | G7: 169964.96 | H7: 188915.94 | I7: 198724.21 | J7: 220700.22 | K7: 256894.25 | L7: 289673.05 | M7: 307659.41 | N7: 336122.68 | O7: =K7/K$7 | P7: =N7/N$7 | Q7: =N7/M7-1 | R7: =(N7/K7)^(1/3)-1
A9: xx | B9: Health Insurance Segmental Growth (INR cr)
B10: Segments | C10: 15 | D10: =C10+1 | E10: =D10+1 | F10: =E10+1 | G10: =F10+1 | H10: =G10+1 | I10: =H10+1 | J10: =I10+1 | K10: =J10+1 | ... N10: =M10+1 | O10: FY23 Mix % | P10: FY26 Mix % | Q10: YoY growth | R10: CAGR (FY23-26) | T10: Key observations - Health Insurance
B11: SAHI | C11: 2896 | D11: 4043 | E11: 5589 | F11: =F27 | G11: =G27 | H11: =H27 | I11: =I27 | J11: =J27 | K11: =K27 | L11: =L27 | M11: =M27 | N11: =N27 | O11: =K11/K$14 | P11: =N11/N$14 | Q11: =N11/M11-1 | R11: =(N11/K11)^(1/3)-1 | T11: 1. SAHIs gaining market share in health insurance (28% in FY23 to 33% in FY26)
B12: Private | F12: =F14-F11-F13 | G12: =G14-G11-G13 | H12: =H14-H11-H13 | I12: =I14-I11-I13 | J12: =J14-J11-J13 | K12: =K14-K11-K13 | L12: =L14-L11-L13 | M12: =M14-M11-M13 | N12: =N14-N11-N13 | O12: =K12/K$14 | P12: =N12/N$14 | Q12: =N12/M12-1 | R12: =(N12/K12)^(1/3)-1 | T12: 2. Increase in market share for SAHIs and private coming from PSU market share loss
B13: PSUs | F13: 21538.29 | G13: 23518.95 | H13: 24652.07 | I13: 27272.02 | J13: 32954.79 | K13: 39078.11 | L13: 41012.02 | M13: 42245.22 | N13: 42245.22 | O13: =K13/K$14 | P13: =N13/N$14 | Q13: =N13/M13-1 | R13: =(N13/K13)^(1/3)-1
B14: Total | C14: =C4 | D14: =D4 | E14: =E4 | F14: =F4 | G14: =G4 | H14: =H4 | I14: =I4 | J14: =J4 | ... N14: =N4 | O14: =K14/K$14 | P14: =N14/N$14 | Q14: =N14/M14-1 | R14: =(N14/K14)^(1/3)-1
A16: xx | B16: SAHI's growth (INR cr)
B17: Insurer | C17: 15 | D17: =C17+1 | E17: =D17+1 | F17: =E17+1 | G17: =F17+1 | H17: =G17+1 | I17: =H17+1 | J17: =I17+1 | K17: =J17+1 | ... N17: =M17+1 | O17: FY23 Mix % | P17: Market share FY26 | Q17: YoY growth | R17: CAGR (FY23-26) | T17: Key observations - SAHI Growth
B18: Star Health | F18: 4044.65 | G18: 5286.46 | H18: 6731.42 | I18: 9204.49 | J18: 11294.58 | K18: 12757.54 | L18: 15038.78 | M18: 16525.48 | N18: 18435.04 | O18: =K18/K$27 | P18: =N18/N$27 | Q18: =N18/M18-1 | R18: =(N18/K18)^(1/3)-1 | T18: 1. Health industry YoY growth has picked up for FY26 compared to FY25 - 19.5% vs 16% (2y CAGR of 18%)
B19: Care | F19: 987.94 | G19: 1681.33 | H19: 2231.74 | I19: 2334.06 | J19: 3491.45 | K19: 4819.42 | L19: 6658.07 | M19: 8135.35 | N19: 9768.4 | O19: =K19/K$27 | P19: =N19/N$27 | Q19: =N19/M19-1 | R19: =(N19/K19)^(1/3)-1 | T19: 2. Over last 2 years, Niva Bupa grew at 24% CAGR and Care by 21% CAGR; Niva Bupa's FY26 growth has been significantly faster than Care (27.8% vs 20.1%)
B20: Niva Bupa | F20: 743.26 | G20: 914.49 | H20: 1179.04 | I20: 1669.72 | J20: 2749.22 | K20: 3993.02 | L20: 5514.46 | M20: 6634.53 | N20: 8479.66 | O20: =K20/K$27 | P20: =N20/N$27 | Q20: =N20/M20-1 | R20: =(N20/K20)^(1/3)-1 | T20: 3. Aditya Birla is coming up strong among the SAHIs and has grown at 31% YoY (29% 2y CAGR)
B21: Aditya Birla | F21: 230.37 | G21: 423.43 | H21: 755.51 | I21: 1165.84 | J21: 1582.48 | K21: 2556.81 | L21: 3480.83 | M21: 4446.81 | N21: 5825.47 | O21: =K21/K$27 | P21: =N21/N$27 | Q21: =N21/M21-1 | R21: =(N21/K21)^(1/3)-1 | T21: 4. Star continues to face growth issues as it has grown slower than the industry in FY26 (~12%)
B22: Manipal Cigna | F22: 326.54 | G22: 469.48 | H22: 568.16 | I22: 745.79 | J22: 971.59 | K22: 1329.7912 | L22: 1661.68 | M22: 1766.98 | N22: 2170.31 | O22: =K22/K$27 | P22: =N22/N$27 | Q22: =N22/M22-1 | R22: =(N22/K22)^(1/3)-1 | T22: 5. Niva Bupa, Care and Aditya Birla have gained market share every year since FY23; while Star has lost its market share to them evenly
B23: Reliance Health | F23: 0 | G23: 4.09 | H23: 5.98 | I23: -0.01 | J23: 0 | K23: 0 | L23: 0 | M23: 0 | O23: =K23/K$27 | P23: =N23/N$27 | Q23: =N23/M23-1 | R23: =(N23/K23)^(1/3)-1
B24: HDFC Ergo (Incl. Apollo Munich) | F24: 1586.25 | G24: 2014.74 | H24: 2073.84 | I24: 0 | J24: 0 | K24: 0 | L24: 0 | M24: 0 | O24: =K24/K$27 | P24: =N24/N$27 | Q24: =N24/M24-1 | R24: =(N24/K24)^(1/3)-1
B25: Galaxy Health | F25: 0 | G25: 0 | H25: 0 | I25: 0 | J25: 0 | K25: 0 | L25: 0 | M25: 16.08 | N25: 141 | O25: =K25/K$27 | P25: =N25/N$27 | Q25: =N25/M25-1 | R25: nm
B26: Narayana Health | F26: 0 | G26: 0 | H26: 0 | I26: 0 | J26: 0 | K26: 0 | L26: 0 | M26: 2.37 | N26: 43.85 | O26: =K26/K$27 | P26: =N26/N$27 | Q26: =N26/M26-1 | R26: nm
B27: Total | F27: =SUM(F18:F26) | G27: =SUM(G18:G26) | H27: =SUM(H18:H26) | I27: =SUM(I18:I26) | J27: =SUM(J18:J26) | K27: =SUM(K18:K26) | L27: =SUM(L18:L26) | M27: =SUM(M18:M26) | N27: =SUM(N18:N26) | O27: =K27/K$27 | P27: =N27/N$27 | Q27: =N27/M27-1 | R27: =(N27/K27)^(1/3)-1
B29: SAHI's Retail Mix (%)
B30: Insurer | C30: 15 | D30: =C30+1 | E30: =D30+1 | F30: =E30+1 | G30: =F30+1 | H30: =G30+1 | I30: =H30+1 | J30: =I30+1 | K30: =J30+1 | ... N30: =M30+1 | O30: YoY change
B31: Star Health | C31: =IFERROR(C42/C18,"") | D31: =IFERROR(D42/D18,"") | E31: =IFERROR(E42/E18,"") | F31: =IFERROR(F42/F18,"") | G31: =IFERROR(G42/G18,"") | H31: =IFERROR(H42/H18,"") | I31: =IFERROR(I42/I18,"") | J31: =IFERROR(J42/J18,"") | ... N31: =IFERROR(N42/N18,"") | O31: =N31-M31
B32: Care | C32: =IFERROR(C43/C19,"") | D32: =IFERROR(D43/D19,"") | E32: =IFERROR(E43/E19,"") | F32: =IFERROR(F43/F19,"") | G32: =IFERROR(G43/G19,"") | H32: =IFERROR(H43/H19,"") | I32: =IFERROR(I43/I19,"") | J32: =IFERROR(J43/J19,"") | ... N32: =IFERROR(N43/N19,"") | O32: =N32-M32
B33: Niva Bupa | C33: =IFERROR(C44/C20,"") | D33: =IFERROR(D44/D20,"") | E33: =IFERROR(E44/E20,"") | F33: =IFERROR(F44/F20,"") | G33: =IFERROR(G44/G20,"") | H33: =IFERROR(H44/H20,"") | I33: =IFERROR(I44/I20,"") | J33: =IFERROR(J44/J20,"") | ... N33: =IFERROR(N44/N20,"") | O33: =N33-M33
B34: Aditya Birla | C34: =IFERROR(C45/C21,"") | D34: =IFERROR(D45/D21,"") | E34: =IFERROR(E45/E21,"") | F34: =IFERROR(F45/F21,"") | G34: =IFERROR(G45/G21,"") | H34: =IFERROR(H45/H21,"") | I34: =IFERROR(I45/I21,"") | J34: =IFERROR(J45/J21,"") | ... N34: =IFERROR(N45/N21,"") | O34: =N34-M34
B35: Manipal Cigna | C35: =IFERROR(C46/C22,"") | D35: =IFERROR(D46/D22,"") | E35: =IFERROR(E46/E22,"") | F35: =IFERROR(F46/F22,"") | G35: =IFERROR(G46/G22,"") | H35: =IFERROR(H46/H22,"") | I35: =IFERROR(I46/I22,"") | J35: =IFERROR(J46/J22,"") | ... N35: =IFERROR(N46/N22,"") | O35: =N35-M35
B36: Galaxy Health | C36: =IFERROR(C47/C25,"") | D36: =IFERROR(D47/D25,"") | E36: =IFERROR(E47/E25,"") | F36: =IFERROR(F47/F25,"") | G36: =IFERROR(G47/G25,"") | H36: =IFERROR(H47/H25,"") | I36: =IFERROR(I47/I25,"") | J36: =IFERROR(J47/J25,"") | ... N36: =IFERROR(N47/N25,"") | O36: =N36-M36
B37: Narayana Health | C37: =IFERROR(C48/C26,"") | D37: =IFERROR(D48/D26,"") | E37: =IFERROR(E48/E26,"") | F37: =IFERROR(F48/F26,"") | G37: =IFERROR(G48/G26,"") | H37: =IFERROR(H48/H26,"") | I37: =IFERROR(I48/I26,"") | J37: =IFERROR(J48/J26,"") | ... N37: =IFERROR(N48/N26,"") | O37: =N37-M37
B38: Total | C38: =IFERROR(C49/C27,"") | D38: =IFERROR(D49/D27,"") | E38: =IFERROR(E49/E27,"") | F38: =IFERROR(F49/F27,"") | G38: =IFERROR(G49/G27,"") | H38: =IFERROR(H49/H27,"") | I38: =IFERROR(I49/I27,"") | J38: =IFERROR(J49/J27,"") | ... N38: =IFERROR(N49/N27,"") | O38: =N38-M38
A40: xx | B40: SAHI's Retail (INR cr)
B41: Insurer | C41: 15 | D41: =C41+1 | E41: =D41+1 | F41: =E41+1 | G41: =F41+1 | H41: =G41+1 | I41: =H41+1 | J41: =I41+1 | K41: =J41+1 | ... N41: =M41+1 | O41: Market share FY19 | P41: Market share FY26 | Q41: YoY growth | R41: CAGR (FY23-26)
B42: Star Health | F42: 3629.09 | G42: 4678.05 | H42: 5865.75 | I42: 8242.68 | J42: 10129.4 | K42: 11947.5 | L42: 13951.3 | M42: 15413 | N42: 17743 | O42: =K42/$K$49 | P42: =N42/N$49 | Q42: =N42/M42-1 | R42: =(N42/K42)^(1/3)-1
B43: Care | F43: 616.51 | G43: 869 | H43: 1143.08 | I43: 1618.97 | J43: 2170.4 | K43: 2727.7 | L43: 3973.83 | M43: 5111.36 | N43: 6597.6 | O43: =K43/$K$49 | P43: =N43/N$49 | Q43: =N43/M43-1 | R43: =(N43/K43)^(1/3)-1
B44: Niva Bupa | F44: 634.2 | G44: 736.68 | H44: 869.37 | I44: 1355.52 | J44: 2157.34 | K44: 2969.74 | L44: 3839.73 | M44: 4432.5 | N44: 5747.59 | O44: =K44/$K$49 | P44: =N44/N$49 | Q44: =N44/M44-1 | R44: =(N44/K44)^(1/3)-1
B45: Aditya Birla | F45: 76.91 | G45: 198.31 | H45: 349.56 | I45: 558.97 | J45: 680.05 | K45: 835.36 | L45: 1127.23 | M45: 1440.17 | N45: 2163.86 | O45: =K45/$K$49 | P45: =N45/N$49 | Q45: =N45/M45-1 | R45: =(N45/K45)^(1/3)-1
...

Sheet FY26 GWP
A1: xx | B1: GWP growth
B2: Total Health GWP (INR cr) | C2: Previous FY | I2: Current FY | O2: YoY growth | Q2: YoY growth | R2: YoY growth
C3: Q1FY25 | D3: Q2FY25 | E3: H1FY25 | F3: upto Q3FY25 | G3: Q4FY25 | H3: FY25 | I3: Q1FY26 | J3: Q2FY26 | K3: H1FY26 | L3: upto Q3FY26 | M3: Q4FY26 | N3: FY26 | O3: Q1 yoy% | P3: Q2 yoy% | Q3: H1 yoy% | R3: Q4 yoy%
B4: SAHIs >>
B5: Star Health | C5: ='Q1''26 GWP'!F5 | D5: =E5-C5 | E5: 7721.64 | F5: 11466.15 | G5: =H5-F5 | H5: 16526.25 | I5: ='Q1''26 GWP'!J5 | J5: =K5-I5 | K5: 7984.12 | L5: 12518.16 | M5: =N5-L5 | N5: 18435.04 | O5: =IFERROR(I5/C5-1,"nm") | P5: =IFERROR(J5/D5-1,"nm") | Q5: =IFERROR(K5/E5-1,"nm") | R5: =IFERROR(M5/G5-1,"nm")
B6: Care | C6: ='Q1''26 GWP'!F6 | D6: =E6-C6 | E6: 4063.88 | F6: 5860.76 | G6: =H6-F6 | H6: 8113.66 | I6: ='Q1''26 GWP'!J6 | J6: =K6-I6 | K6: 4255.83 | L6: 6698.1 | M6: =N6-L6 | N6: 9768.4 | O6: =IFERROR(I6/C6-1,"nm") | P6: =IFERROR(J6/D6-1,"nm") | Q6: =IFERROR(K6/E6-1,"nm") | R6: =IFERROR(M6/G6-1,"nm")
B7: Niva Bupa | C7: ='Q1''26 GWP'!F7 | D7: =E7-C7 | E7: 3176.24 | F7: 4591.58 | G7: =H7-F7 | H7: 6634.53 | I7: ='Q1''26 GWP'!J7 | J7: =K7-I7 | K7: 3428.75 | L7: 5633.17 | M7: =N7-L7 | N7: 8479.66 | O7: =IFERROR(I7/C7-1,"nm") | P7: =IFERROR(J7/D7-1,"nm") | Q7: =IFERROR(K7/E7-1,"nm") | R7: =IFERROR(M7/G7-1,"nm")
B8: Aditya Birla | C8: ='Q1''26 GWP'!F8 | D8: =E8-C8 | E8: 2045.73 | F8: 2923.94 | G8: =H8-F8 | H8: 4446.81 | I8: ='Q1''26 GWP'!J8 | J8: =K8-I8 | K8: 2611.84 | L8: 4107.01 | M8: =N8-L8 | N8: 5825.47 | O8: =IFERROR(I8/C8-1,"nm") | P8: =IFERROR(J8/D8-1,"nm") | Q8: =IFERROR(K8/E8-1,"nm") | R8: =IFERROR(M8/G8-1,"nm")
B9: Manipal Cigna | C9: ='Q1''26 GWP'!F9 | D9: =E9-C9 | E9: 815.91 | F9: 1187.45 | G9: =H9-F9 | H9: 1767.54 | I9: ='Q1''26 GWP'!J9 | J9: =K9-I9 | K9: 942.91 | L9: 1512.44 | M9: =N9-L9 | N9: 2170.31 | O9: =IFERROR(I9/C9-1,"nm") | P9: =IFERROR(J9/D9-1,"nm") | Q9: =IFERROR(K9/E9-1,"nm") | R9: =IFERROR(M9/G9-1,"nm")
B10: Galaxy Health | C10: ='Q1''26 GWP'!F10 | D10: =E10-C10 | F10: 2.38 | G10: =H10-F10 | H10: 16 | I10: ='Q1''26 GWP'!J10 | J10: =K10-I10 | K10: 38.41 | L10: 71.77 | M10: =N10-L10 | N10: 141 | O10: =IFERROR(I10/C10-1,"nm") | P10: =IFERROR(J10/D10-1,"nm") | Q10: =IFERROR(K10/E10-1,"nm") | R10: =IFERROR(M10/G10-1,"nm")
B11: Narayana Health | C11: ='Q1''26 GWP'!F11 | D11: =E11-C11 | F11: 0 | G11: =H11-F11 | H11: 0 | I11: ='Q1''26 GWP'!J11 | J11: =K11-I11 | K11: 8.7 | L11: 23.95 | M11: =N11-L11 | N11: 43.85 | O11: =IFERROR(I11/C11-1,"nm") | P11: =IFERROR(J11/D11-1,"nm") | Q11: =IFERROR(K11/E11-1,"nm") | R11: =IFERROR(M11/G11-1,"nm")
B12: Private Multi-line >>
B13: HDFC Ergo | C13: ='Q1''26 GWP'!F13 | D13: =E13-C13 | E13: 3042.95 | F13: 4169.66 | G13: =H13-F13 | H13: 5753.1 | I13: ='Q1''26 GWP'!J13 | J13: =K13-I13 | K13: 2844.68 | L13: 4481.45 | M13: =N13-L13 | N13: 6672.73 | O13: =IFERROR(I13/C13-1,"nm") | P13: =IFERROR(J13/D13-1,"nm") | Q13: =IFERROR(K13/E13-1,"nm") | R13: =IFERROR(M13/G13-1,"nm")
B14: ICICI Lombard | C14: ='Q1''26 GWP'!F14 | D14: =E14-C14 | E14: 4012.19 | F14: 5373.71 | G14: =H14-F14 | H14: 7188.3 | I14: ='Q1''26 GWP'!J14 | J14: =K14-I14 | K14: 4193.42 | L14: 6125.41 | M14: =N14-L14 | N14: 8617.28 | O14: =IFERROR(I14/C14-1,"nm") | P14: =IFERROR(J14/D14-1,"nm") | Q14: =IFERROR(K14/E14-1,"nm") | R14: =IFERROR(M14/G14-1,"nm")
B15: Bajaj Allianz | C15: ='Q1''26 GWP'!F15 | D15: =E15-C15 | E15: 3696.28 | F15: 6953.02 | G15: =H15-F15 | H15: 7828.79 | I15: ='Q1''26 GWP'!J15 | J15: =K15-I15 | K15: 3712.69 | L15: 7389.41 | M15: =N15-L15 | N15: 8525.57 | O15: =IFERROR(I15/C15-1,"nm") | P15: =IFERROR(J15/D15-1,"nm") | Q15: =IFERROR(K15/E15-1,"nm") | R15: =IFERROR(M15/G15-1,"nm")
B16: Reliance | C16: ='Q1''26 GWP'!F16 | D16: =E16-C16 | E16: 1136.48 | F16: 1627.82 | G16: =H16-F16 | H16: 1909.11 | I16: ='Q1''26 GWP'!J16 | J16: =K16-I16 | K16: 1593.09 | L16: 2029.02 | M16: =N16-L16 | N16: 2435.35 | O16: =IFERROR(I16/C16-1,"nm") | P16: =IFERROR(J16/D16-1,"nm") | Q16: =IFERROR(K16/E16-1,"nm") | R16: =IFERROR(M16/G16-1,"nm")
B17: SBI GI | C17: ='Q1''26 GWP'!F17 | D17: =E17-C17 | E17: 1253.95 | F17: 1946.87 | G17: =H17-F17 | H17: 3433.69 | I17: ='Q1''26 GWP'!J17 | J17: =K17-I17 | K17: 1700.21 | L17: 2535.61 | M17: =N17-L17 | N17: 4372.94 | O17: =IFERROR(I17/C17-1,"nm") | P17: =IFERROR(J17/D17-1,"nm") | Q17: =IFERROR(K17/E17-1,"nm") | R17: =IFERROR(M17/G17-1,"nm")
B18: PSUs >>
B19: New India | C19: ='Q1''26 GWP'!F19 | D19: =E19-C19 | E19: 10068.08 | F19: 15097.46 | G19: =H19-F19 | H19: 19194.69 | I19: ='Q1''26 GWP'!J19 | J19: =K19-I19 | K19: 11342.68 | L19: 17549.18 | M19: =N19-L19 | N19: 21531.52 | O19: =IFERROR(I19/C19-1,"nm") | P19: =IFERROR(J19/D19-1,"nm") | Q19: =IFERROR(K19/E19-1,"nm") | R19: =IFERROR(M19/G19-1,"nm")
B20: National Insurance | C20: ='Q1''26 GWP'!F20 | D20: =E20-C20 | E20: 3523.3 | F20: 6442.04 | G20: =H20-F20 | H20: 7967.52 | I20: ='Q1''26 GWP'!J20 | J20: =K20-I20 | K20: 3560.11 | L20: 6863.24 | M20: =N20-L20 | N20: 8278.78 | O20: =IFERROR(I20/C20-1,"nm") | P20: =IFERROR(J20/D20-1,"nm") | Q20: =IFERROR(K20/E20-1,"nm") | R20: =IFERROR(M20/G20-1,"nm")
B21: Oriental Insurance | C21: ='Q1''26 GWP'!F21 | D21: =E21-C21 | E21: 4439.12 | F21: 6201.56 | G21: =H21-F21 | H21: 8242.87 | I21: ='Q1''26 GWP'!J21 | J21: =K21-I21 | K21: 4504.31 | L21: 6552.39 | M21: =N21-L21 | N21: 8793.9 | O21: =IFERROR(I21/C21-1,"nm") | P21: =IFERROR(J21/D21-1,"nm") | Q21: =IFERROR(K21/E21-1,"nm") | R21: =IFERROR(M21/G21-1,"nm")
B22: United India | C22: ='Q1''26 GWP'!F22 | D22: =E22-C22 | E22: 3730.57 | F22: 4901.41 | G22: =H22-F22 | H22: 7034.29 | I22: ='Q1''26 GWP'!J22 | J22: =K22-I22 | K22: 3821.36 | L22: 5068.69 | M22: =N22-L22 | N22: 7836.31 | O22: =IFERROR(I22/C22-1,"nm") | P22: =IFERROR(J22/D22-1,"nm") | Q22: =IFERROR(K22/E22-1,"nm") | R22: =IFERROR(M22/G22-1,"nm")
B23: Others | C23: ='Q1''26 GWP'!F23 | D23: =E23-C23 | E23: =E24-SUM(E5:E22) | F23: =F24-SUM(F5:F22) | G23: =H23-F23 | H23: =H24-SUM(H5:H22) | I23: ='Q1''26 GWP'!J23 | J23: =K23-I23 | K23: =K24-SUM(K5:K22) | L23: =L24-SUM(L5:L22) | M23: =M24-SUM(M5:M22) | N23: =N24-SUM(N5:N22) | O23: =IFERROR(I23/C23-1,"nm") | P23: =IFERROR(J23/D23-1,"nm") | Q23: =IFERROR(K23/E23-1,"nm") | R23: =IFERROR(M23/G23-1,"nm")
B24: Total Health GWP (INR cr) | C24: ='Q1''26 GWP'!F24 | D24: =E24-C24 | E24: 59607.16 | F24: 88243.46 | G24: =H24-F24 | H24: 118857.63 | I24: ='Q1''26 GWP'!J24 | J24: =K24-I24 | K24: 64240.4 | L24: 100234.21 | M24: =N24-L24 | N24: 137144.46 | O24: =IFERROR(I24/C24-1,"nm") | P24: =IFERROR(J24/D24-1,"nm") | Q24: =IFERROR(K24/E24-1,"nm") | R24: =IFERROR(M24/G24-1,"nm")
B26: Retail Health GWP (INR cr) | C26: Previous FY | I26: Current FY
C27: =C3 | D27: =D3 | E27: =E3 | G27: Q4FY25 | H27: FY25 | I27: =I3 | J27: =J3 | K27: =K3 | M27: Q4FY26 | N27: FY26 | O27: =O3 | P27: =P3 | Q27: =Q3 | R27: =R3
B28: SAHIs >>
B29: Star Health | C29: ='Q1''26 GWP'!F29 | D29: =E29-C29 | E29: 7033.84 | F29: 10564.2 | G29: =H29-F29 | H29: 15413 | I29: ='Q1''26 GWP'!J29 | J29: =K29-I29 | K29: 7617.66 | L29: 11974.9 | M29: =N29-L29 | N29: 17743 | O29: =IFERROR(I29/C29-1,"nm") | P29: =IFERROR(J29/D29-1,"nm") | Q29: =IFERROR(K29/E29-1,"nm") | R29: =IFERROR(M29/G29-1,"nm")
B30: Care | C30: ='Q1''26 GWP'!F30 | D30: =E30-C30 | E30: 2383.67 | F30: 3541.06 | G30: =H30-F30 | H30: 5111.36 | I30: ='Q1''26 GWP'!J30 | J30: =K30-I30 | K30: 2686.17 | L30: 4367.03 | M30: =N30-L30 | N30: 6597.6 | O30: =IFERROR(I30/C30-1,"nm") | P30: =IFERROR(J30/D30-1,"nm") | Q30: =IFERROR(K30/E30-1,"nm") | R30: =IFERROR(M30/G30-1,"nm")
B31: Niva Bupa | C31: ='Q1''26 GWP'!F31 | D31: =E31-C31 | E31: 2201.31 | F31: 3136 | G31: =H31-F31 | H31: 4432.5 | I31: ='Q1''26 GWP'!J31 | J31: =K31-I31 | K31: 2371.76 | L31: 3817.38 | M31: =N31-L31 | N31: 5747.59 | O31: =IFERROR(I31/C31-1,"nm") | P31: =IFERROR(J31/D31-1,"nm") | Q31: =IFERROR(K31/E31-1,"nm") | R31: =IFERROR(M31/G31-1,"nm")
B32: Aditya Birla | C32: ='Q1''26 GWP'!F32 | D32: =E32-C32 | E32: 703.92 | F32: 996.77 | G32: =H32-F32 | H32: 1440.17 | I32: ='Q1''26 GWP'!J32 | J32: =K32-I32 | K32: 821.31 | L32: 1385.22 | M32: =N32-L32 | N32: 2163.86 | O32: =IFERROR(I32/C32-1,"nm") | P32: =IFERROR(J32/D32-1,"nm") | Q32: =IFERROR(K32/E32-1,"nm") | R32: =IFERROR(M32/G32-1,"nm")
B33: Manipal Cigna | C33: ='Q1''26 GWP'!F33 | D33: =E33-C33 | E33: 390.17 | F33: 576.16 | G33: =H33-F33 | H33: 841.12 | I33: ='Q1''26 GWP'!J33 | J33: =K33-I33 | K33: 444.62 | L33: 725 | M33: =N33-L33 | N33: 1119.03 | O33: =IFERROR(I33/C33-1,"nm") | P33: =IFERROR(J33/D33-1,"nm") | Q33: =IFERROR(K33/E33-1,"nm") | R33: =IFERROR(M33/G33-1,"nm")
B34: Galaxy Health | C34: ='Q1''26 GWP'!F34 | D34: =E34-C34 | F34: 2.38 | G34: =H34-F34 | H34: 13.99 | I34: ='Q1''26 GWP'!J34 | J34: =K34-I34 | K34: 24.06 | L34: 71.77 | M34: =N34-L34 | N34: 97 | O34: =IFERROR(I34/C34-1,"nm") | P34: =IFERROR(J34/D34-1,"nm") | Q34: =IFERROR(K34/E34-1,"nm") | R34: =IFERROR(M34/G34-1,"nm")
B35: Narayana Health | C35: ='Q1''26 GWP'!F35 | D35: =E35-C35 | F35: 0 | G35: =H35-F35 | H35: 0 | I35: ='Q1''26 GWP'!J35 | J35: =K35-I35 | K35: 1.8 | L35: 3.98 | M35: =N35-L35 | N35: 9.05 | O35: =IFERROR(I35/C35-1,"nm") | P35: =IFERROR(J35/D35-1,"nm") | Q35: =IFERROR(K35/E35-1,"nm") | R35: =IFERROR(M35/G35-1,"nm")
B36: Private Multi-line >> | C36: ='Q1''26 GWP'!F36
B37: HDFC Ergo | C37: ='Q1''26 GWP'!F37 | D37: =E37-C37 | E37: 1970.67 | F37: 2879.4 | G37: =H37-F37 | H37: 4212.7 | I37: ='Q1''26 GWP'!J37 | J37: =K37-I37 | K37: 2025.92 | L37: 3334.47 | M37: =N37-L37 | N37: 5155.8 | O37: =IFERROR(I37/C37-1,"nm") | P37: =IFERROR(J37/D37-1,"nm") | Q37: =IFERROR(K37/E37-1,"nm") | R37: =IFERROR(M37/G37-1,"nm")
B38: ICICI Lombard | C38: ='Q1''26 GWP'!F38 | D38: =E38-C38 | E38: 718 | F38: 1059.7 | G38: =H38-F38 | H38: 1556.23 | I38: ='Q1''26 GWP'!J38 | J38: =K38-I38 | K38: 899.21 | L38: 1533.98 | M38: =N38-L38 | N38: 2351.2 | O38: =IFERROR(I38/C38-1,"nm") | P38: =IFERROR(J38/D38-1,"nm") | Q38: =IFERROR(K38/E38-1,"nm") | R38: =IFERROR(M38/G38-1,"nm")
B39: Bajaj Allianz | C39: ='Q1''26 GWP'!F39 | D39: =E39-C39 | E39: 528.3 | F39: 771.38 | G39: =H39-F39 | H39: 1116.83 | I39: ='Q1''26 GWP'!J39 | J39: =K39-I39 | K39: 562.61 | L39: 862.42 | M39: =N39-L39 | N39: 1268.59 | O39: =IFERROR(I39/C39-1,"nm") | P39: =IFERROR(J39/D39-1,"nm") | Q39: =IFERROR(K39/E39-1,"nm") | R39: =IFERROR(M39/G39-1,"nm")
B40: Reliance | C40: ='Q1''26 GWP'!F40 | D40: =E40-C40 | E40: 210.62 | F40: 307.21 | G40: =H40-F40 | H40: 425.68 | I40: ='Q1''26 GWP'!J40 | J40: =K40-I40 | K40: 209.42 | L40: 347.79 | M40: =N40-L40 | N40: 508.1 | O40: =IFERROR(I40/C40-1,"nm") | P40: =IFERROR(J40/D40-1,"nm") | Q40: =IFERROR(K40/E40-1,"nm") | R40: =IFERROR(M40/G40-1,"nm")
B41: SBI GI | C41: ='Q1''26 GWP'!F41 | D41: =E41-C41 | E41: 210.38 | F41: 296.86 | G41: =H41-F41 | H41: 392.37 | I41: ='Q1''26 GWP'!J41 | J41: =K41-I41 | K41: 158.91 | L41: 277.45 | M41: =N41-L41 | N41: 412.99 | O41: =IFERROR(I41/C41-1,"nm") | P41: =IFERROR(J41/D41-1,"nm") | Q41: =IFERROR(K41/E41-1,"nm") | R41: =IFERROR(M41/G41-1,"nm")
...

Sheet Q1'26 GWP
A1: xx | B1: GWP growth
B2: Total Health GWP (INR cr) | C2: Previous FY | G2: Current FY | K2: YoY growth | O2: FY27
C3: Apr'24 | D3: May'24 | E3: Jun'24 | F3: Q1FY25 | G3: Apr'25 | H3: May'25 | I3: Jun'25 | J3: Q1FY26 | K3: Apr'25 | L3: May'25 | M3: Jun'25 | N3: Q1FY26 | O3: Apr'26 | P3: May'26 | Q3: Jun'26 | R3: Q1FY27
B4: SAHIs >>
B5: Star Health | C5: ='[1]Health Portfolio'!$F$72 | D5: 1147.48 | E5: =F5-SUM(C5:D5) | F5: 3475.81 | G5: ='[1]Health Portfolio'!$F$71 | H5: 1187.14 | I5: =J5-SUM(G5:H5) | J5: 3597.29 | K5: =IFERROR(G5/C5-1,"nm") | L5: =IFERROR(H5/D5-1,"nm") | M5: =IFERROR(I5/E5-1,"nm") | N5: =IFERROR(J5/F5-1,"nm")
B6: Care | C6: ='[1]Health Portfolio'!$F$64 | D6: 598.52 | E6: =F6-SUM(C6:D6) | F6: 1929.56 | G6: ='[1]Health Portfolio'!$F$63 | H6: 629.61 | I6: =J6-SUM(G6:H6) | J6: 2049.43 | K6: =IFERROR(G6/C6-1,"nm") | L6: =IFERROR(H6/D6-1,"nm") | M6: =IFERROR(I6/E6-1,"nm") | N6: =IFERROR(J6/F6-1,"nm")
B7: Niva Bupa | C7: ='[1]Health Portfolio'!$F$60 | D7: 497.41 | E7: =F7-SUM(C7:D7) | F7: 1464.17 | G7: ='[1]Health Portfolio'!$F$59 | H7: 546.22 | I7: =J7-SUM(G7:H7) | J7: 1631.9 | K7: =IFERROR(G7/C7-1,"nm") | L7: =IFERROR(H7/D7-1,"nm") | M7: =IFERROR(I7/E7-1,"nm") | N7: =IFERROR(J7/F7-1,"nm")
B8: Aditya Birla | C8: ='[1]Health Portfolio'!$F$62 | D8: 230.9 | E8: =F8-SUM(C8:D8) | F8: 1040.6 | G8: ='[1]Health Portfolio'!$F$61 | H8: 330.73 | I8: =J8-SUM(G8:H8) | J8: 1326.65 | K8: =IFERROR(G8/C8-1,"nm") | L8: =IFERROR(H8/D8-1,"nm") | M8: =IFERROR(I8/E8-1,"nm") | N8: =IFERROR(J8/F8-1,"nm")
B9: Manipal Cigna | C9: ='[1]Health Portfolio'!$F$68 | D9: 117.33 | E9: =F9-SUM(C9:D9) | F9: 410.05 | G9: ='[1]Health Portfolio'!$F$67 | H9: 167.21 | I9: =J9-SUM(G9:H9) | J9: 532 | K9: =IFERROR(G9/C9-1,"nm") | L9: =IFERROR(H9/D9-1,"nm") | M9: =IFERROR(I9/E9-1,"nm") | N9: =IFERROR(J9/F9-1,"nm")
B10: Galaxy Health | C10: ='[1]Health Portfolio'!$F$66 | D10: 0 | E10: =F10-SUM(C10:D10) | F10: 0 | G10: ='[1]Health Portfolio'!$F$65 | H10: 4.03 | I10: =J10-SUM(G10:H10) | J10: 12.28 | K10: =IFERROR(G10/C10-1,"nm") | L10: =IFERROR(H10/D10-1,"nm") | M10: =IFERROR(I10/E10-1,"nm") | N10: =IFERROR(J10/F10-1,"nm")
B11: Narayana Health | C11: ='[1]Health Portfolio'!$F$70 | D11: 0 | E11: =F11-SUM(C11:D11) | F11: 0 | G11: ='[1]Health Portfolio'!$F$69 | H11: 0.79 | I11: =J11-SUM(G11:H11) | J11: 1.72 | K11: =IFERROR(G11/C11-1,"nm") | L11: =IFERROR(H11/D11-1,"nm") | M11: =IFERROR(I11/E11-1,"nm") | N11: =IFERROR(J11/F11-1,"nm")
B12: Private Multi-line >>
B13: HDFC Ergo | C13: ='[1]Health Portfolio'!$F$16 | D13: 447.64 | E13: =F13-SUM(C13:D13) | F13: 1575.71 | G13: ='[1]Health Portfolio'!$F$15 | H13: 410.75 | I13: =J13-SUM(G13:H13) | J13: 1588.29 | K13: =IFERROR(G13/C13-1,"nm") | L13: =IFERROR(H13/D13-1,"nm") | M13: =IFERROR(I13/E13-1,"nm") | N13: =IFERROR(J13/F13-1,"nm")
B14: ICICI Lombard | C14: ='[1]Health Portfolio'!$F$18 | D14: 732.78 | E14: =F14-SUM(C14:D14) | F14: 2583.07 | G14: ='[1]Health Portfolio'!$F$17 | H14: 735.11 | I14: =J14-SUM(G14:H14) | J14: 2595.58 | K14: =IFERROR(G14/C14-1,"nm") | L14: =IFERROR(H14/D14-1,"nm") | M14: =IFERROR(I14/E14-1,"nm") | N14: =IFERROR(J14/F14-1,"nm")
B15: Bajaj Allianz | C15: ='[1]Health Portfolio'!$F$8 | D15: 277.06 | E15: =F15-SUM(C15:D15) | F15: 1378.73 | G15: ='[1]Health Portfolio'!$F$7 | H15: 292.59 | I15: =J15-SUM(G15:H15) | J15: 1309.21 | K15: =IFERROR(G15/C15-1,"nm") | L15: =IFERROR(H15/D15-1,"nm") | M15: =IFERROR(I15/E15-1,"nm") | N15: =IFERROR(J15/F15-1,"nm")
B16: Reliance | C16: ='[1]Health Portfolio'!$F$36 | D16: 138.63 | E16: =F16-SUM(C16:D16) | F16: 741.25 | G16: ='[1]Health Portfolio'!$F$35 | H16: 363.44 | I16: =J16-SUM(G16:H16) | J16: 1022.94 | K16: =IFERROR(G16/C16-1,"nm") | L16: =IFERROR(H16/D16-1,"nm") | M16: =IFERROR(I16/E16-1,"nm") | N16: =IFERROR(J16/F16-1,"nm")
B17: SBI GI | C17: ='[1]Health Portfolio'!$F$40 | D17: 168.21 | E17: =F17-SUM(C17:D17) | F17: 806.52 | G17: ='[1]Health Portfolio'!$F$39 | H17: 181.96 | I17: =J17-SUM(G17:H17) | J17: 1192.44 | K17: =IFERROR(G17/C17-1,"nm") | L17: =IFERROR(H17/D17-1,"nm") | M17: =IFERROR(I17/E17-1,"nm") | N17: =IFERROR(J17/F17-1,"nm")
B18: PSUs >>
B19: New India | C19: ='[1]Health Portfolio'!$F$46 | D19: 968.78 | E19: =F19-SUM(C19:D19) | F19: 5880.51 | G19: ='[1]Health Portfolio'!$F$45 | H19: 1367.98 | I19: =J19-SUM(G19:H19) | J19: 6713.35 | K19: =IFERROR(G19/C19-1,"nm") | L19: =IFERROR(H19/D19-1,"nm") | M19: =IFERROR(I19/E19-1,"nm") | N19: =IFERROR(J19/F19-1,"nm")
B20: National Insurance | C20: ='[1]Health Portfolio'!$F$30 | D20: 426.22 | E20: =F20-SUM(C20:D20) | F20: 1560.42 | G20: ='[1]Health Portfolio'!$F$29 | H20: 348.61 | I20: =J20-SUM(G20:H20) | J20: 1742.56 | K20: =IFERROR(G20/C20-1,"nm") | L20: =IFERROR(H20/D20-1,"nm") | M20: =IFERROR(I20/E20-1,"nm") | N20: =IFERROR(J20/F20-1,"nm")
B21: Oriental Insurance | C21: ='[1]Health Portfolio'!$F$48 | D21: 897.19 | E21: =F21-SUM(C21:D21) | F21: 2749.66 | G21: ='[1]Health Portfolio'!$F$47 | H21: 826.62 | I21: =J21-SUM(G21:H21) | J21: 3642.74 | K21: =IFERROR(G21/C21-1,"nm") | L21: =IFERROR(H21/D21-1,"nm") | M21: =IFERROR(I21/E21-1,"nm") | N21: =IFERROR(J21/F21-1,"nm")
B22: United India | C22: ='[1]Health Portfolio'!$F$50 | D22: 716.98 | E22: =F22-SUM(C22:D22) | F22: 2523.6 | G22: ='[1]Health Portfolio'!$F$49 | H22: 604.73 | I22: =J22-SUM(G22:H22) | J22: 2124.65 | K22: =IFERROR(G22/C22-1,"nm") | L22: =IFERROR(H22/D22-1,"nm") | M22: =IFERROR(I22/E22-1,"nm") | N22: =IFERROR(J22/F22-1,"nm")
B23: Others | C23: =C24-SUM(C19:C22,C13:C17,C5:C11) | D23: =D24-SUM(D19:D22,D13:D17,D5:D11) | E23: =F23-SUM(C23:D23) | F23: =F24-SUM(F19:F22,F13:F17,F5:F11) | G23: =G24-SUM(G19:G22,G13:G17,G5:G11) | H23: =H24-SUM(H19:H22,H13:H17,H5:H11) | I23: =J23-SUM(G23:H23) | J23: =J24-SUM(J19:J22,J13:J17,J5:J11) | K23: =IFERROR(G23/C23-1,"nm") | L23: =IFERROR(H23/D23-1,"nm") | M23: =IFERROR(I23/E23-1,"nm") | N23: =IFERROR(J23/F23-1,"nm")
B24: Total Health GWP (INR cr) | C24: ='[1]Health Portfolio'!$F$77 | D24: 8344.58 | E24: =F24-SUM(C24:D24) | F24: 32236.7 | G24: ='[1]Health Portfolio'!$F$76 | H24: 9118.54 | I24: =J24-SUM(G24:H24) | J24: 35543.33 | K24: =IFERROR(G24/C24-1,"nm") | L24: =IFERROR(H24/D24-1,"nm") | M24: =IFERROR(I24/E24-1,"nm") | N24: =IFERROR(J24/F24-1,"nm")
B26: Retail Health GWP (INR cr) | C26: Previous FY | G26: Current FY | K26: YoY growth
C27: Apr'24 | D27: May'24 | E27: Jun'24 | F27: Q1FY25 | G27: Apr'25 | H27: May'25 | I27: Jun'25 | J27: Q1FY26 | K27: Apr'25 | L27: May'25 | M27: Jun'25 | N27: Q1FY26
B28: SAHIs >>
B29: Star Health | C29: ='[1]Health Portfolio'!$B$72 | D29: 1044.25 | E29: =F29-SUM(C29:D29) | F29: 3101.09 | G29: ='[1]Health Portfolio'!$B$71 | H29: 1131.21 | I29: =J29-SUM(G29:H29) | J29: 3385.78 | K29: =IFERROR(G29/C29-1,"nm") | L29: =IFERROR(H29/D29-1,"nm") | N29: =IFERROR(J29/F29-1,"nm")
B30: Care | C30: ='[1]Health Portfolio'!$B$64 | D30: 351.9 | E30: =F30-SUM(C30:D30) | F30: 1072.45 | G30: ='[1]Health Portfolio'!$B$63 | H30: 395.31 | I30: =J30-SUM(G30:H30) | J30: 1220.45 | K30: =IFERROR(G30/C30-1,"nm") | L30: =IFERROR(H30/D30-1,"nm") | N30: =IFERROR(J30/F30-1,"nm")
B31: Niva Bupa | C31: ='[1]Health Portfolio'!$B$60 | D31: 343.55 | E31: =F31-SUM(C31:D31) | F31: 990.57 | G31: ='[1]Health Portfolio'!$B$59 | H31: 374.95 | I31: =J31-SUM(G31:H31) | J31: 1092.38 | K31: =IFERROR(G31/C31-1,"nm") | L31: =IFERROR(H31/D31-1,"nm") | N31: =IFERROR(J31/F31-1,"nm")
B32: Aditya Birla | C32: ='[1]Health Portfolio'!$B$62 | D32: 109.1 | E32: =F32-SUM(C32:D32) | F32: 318.59 | G32: ='[1]Health Portfolio'!$B$61 | H32: 127.05 | I32: =J32-SUM(G32:H32) | J32: 369.61 | K32: =IFERROR(G32/C32-1,"nm") | L32: =IFERROR(H32/D32-1,"nm") | N32: =IFERROR(J32/F32-1,"nm")
B33: Manipal Cigna | C33: ='[1]Health Portfolio'!$B$68 | D33: 59.41 | E33: =F33-SUM(C33:D33) | F33: 176.82 | G33: ='[1]Health Portfolio'!$B$67 | H33: 69.26 | I33: =J33-SUM(G33:H33) | J33: 206.13 | K33: =IFERROR(G33/C33-1,"nm") | L33: =IFERROR(H33/D33-1,"nm") | N33: =IFERROR(J33/F33-1,"nm")
B34: Galaxy Health | C34: ='[1]Health Portfolio'!$B$66 | D34: 0 | E34: =F34-SUM(C34:D34) | F34: 0 | G34: ='[1]Health Portfolio'!$B$65 | H34: 2.79 | I34: =J34-SUM(G34:H34) | J34: 8.72 | K34: =IFERROR(G34/C34-1,"nm") | L34: =IFERROR(H34/D34-1,"nm") | N34: =IFERROR(J34/F34-1,"nm")
B35: Narayana Health | C35: ='[1]Health Portfolio'!$B$70 | D35: 0 | E35: =F35-SUM(C35:D35) | F35: 0 | G35: ='[1]Health Portfolio'!$B$69 | H35: 0.79 | I35: =J35-SUM(G35:H35) | J35: 1.72 | K35: =IFERROR(G35/C35-1,"nm") | L35: =IFERROR(H35/D35-1,"nm") | N35: =IFERROR(J35/F35-1,"nm")
B36: Private Multi-line >>
B37: HDFC Ergo | C37: ='[1]Health Portfolio'!$B$16 | D37: 305.9 | E37: =F37-SUM(C37:D37) | F37: 895.7 | G37: ='[1]Health Portfolio'!$B$15 | H37: 311.16 | I37: =J37-SUM(G37:H37) | J37: 927.85 | K37: =IFERROR(G37/C37-1,"nm") | L37: =IFERROR(H37/D37-1,"nm") | N37: =IFERROR(J37/F37-1,"nm")
B38: ICICI Lombard | C38: ='[1]Health Portfolio'!$B$18 | D38: 98.44 | E38: =F38-SUM(C38:D38) | F38: 292.7 | G38: ='[1]Health Portfolio'!$B$17 | H38: 129.99 | I38: =J38-SUM(G38:H38) | J38: 387.03 | K38: =IFERROR(G38/C38-1,"nm") | L38: =IFERROR(H38/D38-1,"nm") | N38: =IFERROR(J38/F38-1,"nm")
B39: Bajaj Allianz | C39: ='[1]Health Portfolio'!$B$8 | D39: 77.02 | E39: =F39-SUM(C39:D39) | F39: 229.02 | G39: ='[1]Health Portfolio'!$B$7 | H39: 85.39 | I39: =J39-SUM(G39:H39) | J39: 261.38 | K39: =IFERROR(G39/C39-1,"nm") | L39: =IFERROR(H39/D39-1,"nm") | N39: =IFERROR(J39/F39-1,"nm")
B40: Reliance | C40: ='[1]Health Portfolio'!$B$36 | D40: 32.02 | E40: =F40-SUM(C40:D40) | F40: 96.3 | G40: ='[1]Health Portfolio'!$B$35 | H40: 31.23 | I40: =J40-SUM(G40:H40) | J40: 95.16 | K40: =IFERROR(G40/C40-1,"nm") | L40: =IFERROR(H40/D40-1,"nm") | N40: =IFERROR(J40/F40-1,"nm")
B41: SBI GI | C41: ='[1]Health Portfolio'!$B$40 | D41: 35.39 | E41: =F41-SUM(C41:D41) | F41: 102.6 | G41: ='[1]Health Portfolio'!$B$39 | H41: 25.96 | I41: =J41-SUM(G41:H41) | J41: 74.39 | K41: =IFERROR(G41/C41-1,"nm") | L41: =IFERROR(H41/D41-1,"nm") | N41: =IFERROR(J41/F41-1,"nm")
...

Sheet SAHIs comparison
A1: xx | B1: Detailed comparison of SAHIs
C3: Niva Bupa | P3: Star | AC3: Care | AP3: Manipal Cigna | AX3: Aditya Birla
B4: Niva Bupa | C4: FY23 | D4: FY24 | E4: FY25 | F4: FY26 | G4: FY26 growth | H4: H1FY25 | I4: upto Q3FY25 | J4: Q4FY25 | K4: H1FY26 | L4: upto Q3FY26 | M4: Q4FY26 | N4: Q4 Growth | P4: FY23 | Q4: FY24 | R4: FY25 | S4: FY26 | T4: FY26 growth | U4: H1FY25 | V4: upto Q3FY25 | W4: Q4FY25 | X4: H1FY26 | Y4: upto Q3FY26 | Z4: Q4FY26 | AA4: Q4 growth | AC4: FY23 | AD4: FY24 | AE4: FY25 | AF4: FY26 | AG4: FY26 growth | AH4: Q1FY25 | AI4: YTD Q3 FY25 | AJ4: Q4FY25 | AK4: Q1FY26 | AL4: YTD Q3FY26 | AM4: Q4FY26 | AN4: Q4 growth | AP4: FY23 | AQ4: FY24 | AR4: FY25 | AS4: YoY growth | AT4: Q1FY25 | AU4: Q1FY26 | AV4: YoY growth | AX4: FY23 | AY4: FY24 | AZ4: FY25 | BA4: YoY growth | BB4: Q1FY25 | BC4: Q1FY26 | BD4: YoY growth
B5: Retail GWP | C5: 2969.74 | D5: 3839.73 | E5: 4432.5 | F5: 5747.59 | G5: =F5/E5-1 | H5: 2201.31 | I5: 3136 | J5: =E5-I5 | K5: 2371.76 | L5: 3817.38 | M5: =F5-L5 | N5: =M5/J5-1 | P5: 11947.5 | Q5: 13951.2 | R5: 15413 | S5: ='FY26 GWP'!N29 | T5: =S5/R5-1 | U5: ='FY26 GWP'!E29 | W5: ='FY26 GWP'!G29 | X5: ='FY26 GWP'!K29 | Z5: ='FY26 GWP'!M29 | AA5: =Z5/W5-1 | AC5: 2727.7 | AD5: 3973.83 | AE5: 5111.36 | AF5: ='FY26 GWP'!N30 | AG5: =AF5/AE5-1 | AH5: ='Q1''26 GWP'!F30 | AJ5: ='FY26 GWP'!G30 | AK5: ='Q1''26 GWP'!J30 | AM5: ='FY26 GWP'!M30 | AN5: =AM5/AJ5-1 | AP5: 578.57 | AQ5: 746.08 | AR5: 841.12 | AS5: =AR5/AQ5-1 | AV5: =AU5/AT5-1 | AX5: 835.36 | AY5: 1127.23 | AZ5: 1440.17 | BA5: =AZ5/AY5-1 | BD5: =BC5/BB5-1
B6: Group and others GWP | C6: =C7-C5 | D6: =D7-D5 | E6: =E7-E5 | F6: =F7-F5 | G6: =F6/E6-1 | H6: =H7-H5 | I6: =I7-I5 | J6: =J7-J5 | K6: =K7-K5 | L6: =L7-L5 | M6: =M7-M5 | N6: =M6/J6-1 | P6: =P7-P5 | Q6: =Q7-Q5 | R6: =R7-R5 | S6: =S7-S5 | T6: =S6/R6-1 | U6: =U7-U5 | W6: =W7-W5 | X6: =X7-X5 | Z6: =Z7-Z5 | AA6: =Z6/W6-1 | AC6: =AC7-AC5 | AD6: =AD7-AD5 | AE6: =AE7-AE5 | AF6: =AF7-AF5 | AG6: =AF6/AE6-1 | AH6: =AH7-AH5 | AJ6: =AJ7-AJ5 | AK6: =AK7-AK5 | AM6: =AM7-AM5 | AN6: =AM6/AJ6-1 | AP6: 748.78 | AQ6: 909.84 | AR6: 923.59 | AS6: =AR6/AQ6-1 | AV6: =AU6/AT6-1 | AX6: 1721.15 | AY6: 2319.92 | AZ6: 2956.87 | BA6: =AZ6/AY6-1 | BD6: =BC6/BB6-1
B7: Total GWP | C7: 4073 | D7: 5608 | E7: 6762.23 | F7: 8585.92 | G7: =F7/E7-1 | H7: 3241.51 | I7: 4591.58 | J7: =E7-I7 | K7: 3474.57 | L7: 5633.17 | M7: =F7-L7 | N7: =M7/J7-1 | P7: 12952 | Q7: 15255 | R7: 16716.2 | S7: 18605.53 | T7: =S7/R7-1 | U7: ='FY26 GWP'!E5 | V7: 11603.14 | W7: =R7-V7 | X7: ='FY26 GWP'!K5 | Y7: 12638.44 | Z7: =S7-Y7 | AA7: =Z7/W7-1 | AC7: 5142 | AD7: 6864 | AE7: 8318.25 | AF7: 10031.29 | AG7: =AF7/AE7-1 | AH7: 1931 | AI7: 5996.67 | AJ7: =AE7-AI7 | AK7: 2049 | AL7: 6878.91 | AM7: =AF7-AL7 | AN7: =AM7/AJ7-1 | AP7: 1359.7912 | AQ7: 1691.5 | AR7: 1797 | AS7: =AR7/AQ7-1 | AT7: =#REF!+#REF! | AU7: =#REF!+#REF! | AV7: =AU7/AT7-1 | AX7: 2717.03 | AY7: 3701.31 | AZ7: 4821.7 | BA7: =AZ7/AY7-1 | BB7: =#REF!+#REF! | BC7: =#REF!+#REF! | BD7: =BC7/BB7-1
B8: Retail market share % | C8: 0.083828468 | D8: 0.090988108 | E8: 0.093727658 | F8: ='Industry Growth'!P56 | H8: =H5/'FY26 GWP'!E48 | J8: =J5/'FY26 GWP'!G48 | K8: =K5/'FY26 GWP'!K48 | M8: =M5/'FY26 GWP'!M48 | P8: 0.33724859 | Q8: 0.33059441 | R8: 0.32591639 | S8: ='Industry Growth'!P54 | U8: =U5/'FY26 GWP'!E48 | W8: =W5/'FY26 GWP'!G48 | X8: =X5/'FY26 GWP'!K48 | Z8: =Z5/'FY26 GWP'!M48 | AC8: 0.076996273 | AD8: 0.094165807 | AE8: 0.108 | AF8: ='Industry Growth'!P55 | AH8: =AH5/'Q1''26 GWP'!F48 | AJ8: =AJ5/'FY26 GWP'!G48 | AK8: =AK5/'Q1''26 GWP'!J48 | AM8: =AM5/'FY26 GWP'!M48 | AP8: 0.016 | AQ8: 0.0177 | AR8: 0.0178 | AX8: 0.024 | AY8: 0.027 | AZ8: 0.03
B9: Overall health market share % | C9: 0.044043963 | D9: 0.05059217 | E9: 0.05589894 | F9: 0.061830132 | H9: =H7/'FY26 GWP'!E24 | J9: =J7/'FY26 GWP'!G24 | K9: =H7/'FY26 GWP'!K24 | M9: =M7/'FY26 GWP'!M24 | P9: 0.14071458 | Q9: 0.13796691 | R9: 0.1392 | S9: 0.1344206 | U9: =U7/'FY26 GWP'!E24 | W9: =W7/'FY26 GWP'!G24 | X9: =X7/'FY26 GWP'!K24 | Z9: =Z7/'FY26 GWP'!M24 | AC9: 0.053165046 | AD9: 0.06107537 | AE9: 0.068544032 | AF9: 0.071227084 | AH9: =AH7/'Q1''26 GWP'!F24 | AJ9: =AJ7/'FY26 GWP'!G24 | AK9: =AK7/'Q1''26 GWP'!J24 | AM9: =AM7/'FY26 GWP'!M24 | AP9: 0.0147 | AQ9: 0.0152 | AR9: 0.0149 | AX9: 0.028 | AY9: 0.032 | AZ9: 0.037
B11: NWP | C11: 3183 | D11: 4421 | E11: 5369.43 | F11: 6806.3 | G11: =F11/E11-1 | H11: 2544.89 | J11: 1672.1 | K11: 2737.93 | M11: 2301.7 | N11: =M11/J11-1 | P11: 12319 | Q11: 14067 | R11: 15525.22 | S11: 17650.25 | T11: =S11/R11-1 | W11: 4360.91 | Z11: 5598.57 | AA11: =Z11/W11-1 | AC11: 4591 | AD11: 6047 | AE11: 6732.71 | AF11: =AF7*80% | AG11: =AF11/AE11-1 | AH11: 1716 | AJ11: 1805.54 | AK11: 1652 | AM11: =AM7*80% | AN11: =AM11/AJ11-1 | AP11: 1301.1534 | AQ11: 1617.9101 | AR11: 1876.34 | AS11: =AR11/AQ11-1 | AV11: =AU11/AT11-1 | AX11: 2254.77 | AY11: 2930.9 | AZ11: 3647.29 | BA11: =AZ11/AY11-1 | BD11: =BC11/BB11-1
B12: NEP | C12: 2663 | D12: 3811 | E12: 4894.46 | F12: 6067.6 | G12: =F12/E12-1 | H12: 2231.24 | J12: 1527.5 | K12: 2642.04 | M12: 1972 | N12: =M12/J12-1 | P12: 11262 | Q12: 12938 | R12: 14822.2 | S12: 16597 | T12: =S12/R12-1 | W12: 4250.44 | Z12: 4327.15 | AA12: =Z12/W12-1 | AC12: 3932 | AD12: 5329 | AE12: 6347.22 | AF12: 7256 | AG12: =AF12/AE12-1 | AH12: 1445 | AJ12: 1786 | AK12: 1581 | AM12: 2133 | AN12: =AM12/AJ12-1 | AP12: 1117.7741 | AQ12: 1459.2404 | AR12: 1747.44 | AS12: =AR12/AQ12-1 | AV12: =AU12/AT12-1 | AX12: 1837.8 | AY12: 2600.12 | AZ12: 3304.05 | BA12: =AZ12/AY12-1 | BD12: =BC12/BB12-1
B13: NWP / GWP (Net retention) | C13: =C11/C7 | D13: =D11/D7 | E13: =E11/E7 | F13: =F11/F7 | H13: =H11/H7 | I13: =I11/I7 | J13: =J11/J7 | K13: =K11/K7 | L13: =L11/L7 | M13: =M11/M7 | P13: =P11/P7 | Q13: =Q11/Q7 | R13: =R11/R7 | S13: =S11/S7 | U13: =U11/U7 | W13: =W11/W7 | X13: =X11/X7 | Y13: =Y11/Y7 | Z13: =Z11/Z7 | AC13: =AC11/AC7 | AD13: =AD11/AD7 | AE13: =AE11/AE7 | AF13: =AF11/AF7 | AH13: =AH11/AH7 | AJ13: =AJ11/AJ7 | AK13: =AK11/AK7 | AL13: =AL11/AL7 | AM13: =AM11/AM7 | AP13: =AP11/AP7 | AQ13: =AQ11/AQ7 | AR13: =AR11/AR7 | AT13: =AT11/AT7 | AU13: =AU11/AU7 | AX13: =AX11/AX7 | AY13: =AY11/AY7 | AZ13: =AZ11/AZ7 | BB13: =BB11/BB7 | BC13: =BC11/BC7
B14: NEP / NWP | C14: =C12/C11 | D14: =D12/D11 | E14: =E12/E11 | F14: =F12/F11 | H14: =H12/H11 | I14: =I12/I11 | J14: =J12/J11 | K14: =K12/K11 | L14: =L12/L11 | M14: =M12/M11 | P14: =P12/P11 | Q14: =Q12/Q11 | R14: =R12/R11 | S14: =S12/S11 | U14: =U12/U11 | W14: =W12/W11 | X14: =X12/X11 | Y14: =Y12/Y11 | Z14: =Z12/Z11 | AC14: =AC12/AC11 | AD14: =AD12/AD11 | AE14: =AE12/AE11 | AF14: =AF12/AF11 | AH14: =AH12/AH11 | AJ14: =AJ12/AJ11 | AK14: =AK12/AK11 | AL14: =AL12/AL11 | AM14: =AM12/AM11 | AP14: =AP12/AP11 | AQ14: =AQ12/AQ11 | AR14: =AR12/AR11 | AT14: =AT12/AT11 | AU14: =AU12/AU11 | AX14: =AX12/AX11 | AY14: =AY12/AY11 | AZ14: =AZ12/AZ11 | BB14: =BB12/BB11 | BC14: =BC12/BC11
B16: IGAAP
B17: PAT | C17: 12.5 | D17: 81.85 | E17: 213.52 | F17: 130.8 | G17: =F17/E17-1 | H17: -5.89 | J17: 206.1 | K17: -126.86 | M17: 345.2 | N17: =M17/J17-1 | P17: 619 | Q17: 845 | R17: 645.86 | S17: 557 | T17: =S17/R17-1 | U17: 575 | W17: 1 | X17: 430 | Z17: 111 | AA17: =Z17/W17-1 | AC17: 246 | AD17: 305 | AE17: 154.81 | AF17: 12 | AG17: =AF17/AE17-1 | AH17: 20 | AJ17: 144 | AK17: -15 | AM17: 79 | AN17: =AM17/AJ17-1 | AP17: -200.9294 | AQ17: -131.8339 | AR17: -187.97 | AS17: =AR17/AQ17-1 | AV17: =AU17/AT17-1 | AX17: -218.78 | AY17: -184.39 | AZ17: 5.13 | BA17: =AZ17/AY17-1 | BD17: =BC17/BB17-1
B18: PAT% (on GWP) | C18: =C17/C7 | D18: =D17/D7 | E18: =E17/E7 | F18: =F17/F7 | H18: =H17/H7 | I18: =I17/I7 | J18: =J17/J7 | K18: =K17/K7 | L18: =L17/L7 | M18: =M17/M7 | P18: =P17/P7 | Q18: =Q17/Q7 | R18: =R17/R7 | S18: =S17/S7 | U18: =U17/U7 | W18: =W17/W7 | X18: =X17/X7 | Y18: =Y17/Y7 | Z18: =Z17/Z7 | AC18: =AC17/AC7 | AD18: =AD17/AD7 | AE18: =AE17/AE7 | AF18: =AF17/AF7 | AH18: =AH17/AH7 | AJ18: =AJ17/AJ7 | AK18: =AK17/AK7 | AL18: =AL17/AL7 | AM18: =AM17/AM7 | AP18: =AP17/AP7 | AQ18: =AQ17/AQ7 | AR18: =AR17/AR7 | AT18: =AT17/AT7 | AU18: =AU17/AU7 | AX18: =AX17/AX7 | AY18: =AY17/AY7 | AZ18: =AZ17/AZ7 | BB18: =BB17/BB7 | BC18: =BC17/BC7
B19: Claims ratio | C19: 0.54 | D19: 0.5902 | E19: 0.61222689 | F19: 0.681 | H19: 0.625 | J19: 0.5641 | K19: 0.743 | M19: 0.5676 | P19: 0.65 | Q19: 0.665 | R19: 0.70295705 | S19: 0.685 | U19: 0.702 | W19: 0.685 | X19: 0.705 | Z19: 0.648 | AC19: 0.54 | AD19: 0.58 | AE19: 0.64530456 | AF19: 0.696 | AH19: 0.67 | AJ19: 0.59 | AK19: 0.77 | AM19: 0.594 | AP19: 0.64663254 | AQ19: 0.63783075 | AR19: 0.74814014 | AX19: 0.64676243 | AY19: 0.68308386 | AZ19: 0.71504063
B20: Expense ratio | C20: =C21-C19 | D20: =D21-D19 | E20: 0.39998659 | F20: 0.353 | H20: 0.41 | J20: =J21-J19 | K20: 0.399 | M20: =M21-M19 | P20: =P21-P19 | Q20: =Q21-Q19 | R20: 0.3079718 | S20: 0.319 | U20: 0.309 | W20: 0.299 | X20: 0.324 | Z20: 0.299 | AC20: =AC21-AC19 | AD20: =AD21-AD19 | AE20: 0.38310428 | AF20: 0.371 | AH20: =AH21-AH19 | AJ20: =AJ21-AJ19 | AK20: =AK21-AK19 | AM20: =AM21-AM19 | AP20: 0.50481388 | AQ20: 0.46616774 | AR20: 0.39958643 | AX20: 0.44963344 | AY20: 0.41696748 | AZ20: 0.3331734
B21: Combined ratio | C21: 0.97 | D21: 0.9879 | E21: 1.0122135 | F21: 1.034 | H21: =SUM(H19:H20) | I21: =SUM(I19:I20) | J21: 0.9278 | K21: =SUM(K19:K20) | L21: =SUM(L19:L20) | M21: 0.8612 | P21: 0.953 | Q21: 0.967 | R21: 1.0109289 | S21: 1.004 | U21: 1.011 | W21: 0.992 | X21: 1.03 | Z21: 0.947 | AC21: 0.92 | AD21: 0.95 | AE21: 1.0284088 | AF21: =AF19+AF20 | AH21: 1.01 | AJ21: 0.967 | AK21: 1.1 | AM21: 0.999 | AP21: =SUM(AP19:AP20) | AQ21: =SUM(AQ19:AQ20) | AR21: =SUM(AR19:AR20) | AX21: =SUM(AX19:AX20) | AY21: =SUM(AY19:AY20) | AZ21: =SUM(AZ19:AZ20)
B22: EOM (reported) | C22: 0.41 | D22: 0.3931 | E22: 0.3922 | F22: 0.337 | H22: 0.4 | J22: 0.3633 | K22: 0.363 | M22: 0.2849 | P22: 0.302 | Q22: 0.3066 | R22: 0.3109 | S22: 0.3021 | W22: 0.2805 | Z22: 0.2805 | AC22: 0.4 | AD22: 0.37 | AE22: 0.36 | AF22: 0.36 | AH22: 0.35 | AJ22: 0.35 | AK22: 0.34 | AM22: NA | AP22: 0.49 | AQ22: 0.45 | AR22: 0.42 | AX22: 0.43 | AY22: 0.41 | AZ22: 0.39
B24: IFRS
B25: PAT | C25: 8.5 | D25: 106 | E25: 203 | F25: 366.1 | G25: =F25/E25-1 | H25: 59.5 | J25: 83.4 | K25: 132 | M25: 157.8 | N25: =M25/J25-1 | Q25: 1103 | R25: 787 | S25: 911 | T25: =S25/R25-1 | U25: 428 | W25: 271 | X25: 518 | Z25: -55 | AA25: =Z25/W25-1 | AE25: 290 | AF25: 387 | AJ25: NA | AM25: NA | AP25: -200.9294 | AQ25: -131.8339 | AR25: -187.97 | AS25: =AR25/AQ25-1 | AV25: =AU25/AT25-1 | AX25: -218.78 | AY25: -184.39 | AZ25: 5.13 | BA25: =AZ25/AY25-1 | BD25: =BC25/BB25-1
B26: PAT% (on GWP) | D26: =D25/D7 | E26: =E25/E7 | F26: =F25/F7 | H26: =H25/H7 | I26: =I25/I7 | J26: =J25/J7 | K26: =K25/K7 | L26: =L25/L7 | M26: =M25/M7 | Q26: =Q25/Q7 | R26: =R25/R7 | S26: =S25/S7 | U26: =U25/U7 | W26: =W25/W7 | X26: =X25/X7 | Y26: =Y25/Y7 | Z26: =Z25/Z7 | AE26: =AE25/AE7 | AF26: =AF25/AF7 | AJ26: NA | AM26: NA | AP26: =AP25/AP10 | AQ26: =AQ25/AQ10 | AR26: =AR25/AR10 | AT26: =AT25/AT10 | AU26: =AU25/AU10 | AX26: =AX25/AX10 | AY26: =AY25/AY10 | AZ26: =AZ25/AZ10 | BB26: =BB25/BB10 | BC26: =BC25/BC10
B27: Claims ratio | D27: 0.629 | E27: 0.638 | F27: 0.649 | J27: NA | K27: NA | L27: NA | M27: NA | Q27: 0.665 | R27: 0.707 | S27: 0.687 | W27: 0.692 | Z27: 0.652 | AE27: 0.66 | AF27: 0.65 | AJ27: NA | AK27: NA | AL27: NA | AM27: NA
B28: Expense ratio | D28: =D29-D27 | E28: =E29-E27 | F28: =F29-F27 | J28: NA | K28: NA | L28: NA | M28: NA | Q28: 0.307 | R28: 0.304 | S28: 0.301 | W28: 0.292 | Z28: 0.305 | AE28: 0.366 | AF28: 0.365 | AJ28: NA | AK28: NA | AL28: NA | AM28: NA
B29: Combined ratio | D29: 1.03 | E29: 1.03 | F29: 1.014 | J29: 1.02 | K29: NA | L29: NA | M29: 0.974 | Q29: =Q27+Q28 | R29: =R27+R28 | S29: =S27+S28 | W29: =W27+W28 | X29: =X27+X28 | Y29: =Y27+Y28 | Z29: =Z27+Z28 | AE29: =AE27+AE28 | AF29: =AF27+AF28 | AJ29: NA | AK29: NA | AL29: NA | AM29: NA
B30: EOM (reported) | C30: NA | D30: NA | E30: NA | F30: NA | J30: NA | K30: NA | L30: NA | M30: NA | P30: NA | Q30: NA | R30: NA | S30: NA | W30: NA | X30: NA | Y30: NA | Z30: NA | AC30: NA | AD30: NA | AE30: NA | AF30: NA | AJ30: NA | AK30: NA | AL30: NA | AM30: NA
B32: Solvency | C32: 1.67 | D32: 2.55 | E32: 3.03 | F32: 2.49 | H32: 2.25 | J32: NA | K32: NA | L32: NA | M32: NA | P32: 2.21 | Q32: 2.14 | R32: 2.21 | S32: 2.05 | W32: =R32 | Z32: =S32 | AC32: 1.82 | AD32: 1.74 | AE32: 1.68 | AF32: 1.68 | AH32: 1.64 | AJ32: 1.68 | AK32: 1.66 | AM32: 1.68 | AP32: 1.56 | AQ32: 1.66 | AR32: 1.76 | AX32: 2.63 | AY32: 1.67 | AZ32: 1.84
B33: Net worth | C33: 831.12 | D33: 2049.77 | E33: 3060.84 | F33: 3219 | G33: =F33/E33-1 | H33: 2065 | J33: =E33 | K33: 2956 | M33: =F33 | N33: =M33/J33-1 | P33: 5433.94 | Q33: 6055.02 | R33: 6377.78 | S33: 7588.66 | T33: =S33/R33-1 | W33: =R33 | Z33: =S33 | AA33: =Z33/W33-1 | AC33: 1749.17 | AD33: 2169.821 | AE33: 2331.2 | AF33: 2666 | AG33: =AF33/AE33-1 | AH33: =972+0.39+1219 | AJ33: =AE33 | AK33: =974+1342 | AM33: =AF33 | AN33: =AM33/AJ33-1 | AP33: 326.7251 | AQ33: 471.1 | AR33: 508.33 | AS33: =AR33/AQ33-1 | AV33: =AU33/AT33-1 | AX33: 1253 | AY33: 1073.37 | AZ33: 1478.97 | BA33: =AZ33/AY33-1 | BD33: =BC33/BB33-1
B34: Investment AUM | C34: 3467.96 | D34: 5601.05 | E34: 8395.43 | F34: 9669.7 | G34: =F34/E34-1 | H34: 5965 | J34: =E34 | K34: 8481 | M34: =F34 | N34: =M34/J34-1 | P34: 13701.46 | Q34: 15491 | R34: 17898 | S34: 21007 | T34: =S34/R34-1 | U34: 16431 | W34: =R34 | X34: 18672 | Z34: =S34 | AA34: =Z34/W34-1 | AC34: 5176.1 | AD34: 6728.76 | AE34: 8592.9 | AF34: 10944 | AG34: =AF34/AE34-1 | AH34: =2184+4650 | AJ34: =AE34 | AK34: =2362+6410 | AM34: =AF34 | AN34: =AM34/AJ34-1 | AP34: 1472.6524 | AQ34: 1734.42 | AR34: 2077.88 | AS34: =AR34/AQ34-1 | AV34: =AU34/AT34-1 | AX34: 2971.25 | AY34: 3452.54 | AZ34: 4427.81 | BA34: =AZ34/AY34-1 | BD34: =BC34/BB34-1
B35: Investment leverage | C35: =C34/C33 | D35: =D34/D33 | E35: =E34/E33 | F35: =F34/F33 | H35: =H34/H33 | I35: =I34/I33 | J35: =J34/J33 | K35: =K34/K33 | L35: =L34/L33 | M35: =M34/M33 | P35: =P34/P33 | Q35: =Q34/Q33 | R35: =R34/R33 | S35: =S34/S33 | U35: =U34/U33 | W35: =R35 | X35: =X34/X33 | Z35: =S35 | AC35: =AC34/AC33 | AD35: =AD34/AD33 | AE35: =AE34/AE33 | AF35: =AF34/AF33 | AH35: =AH34/AH33 | AJ35: =AJ34/AJ33 | AK35: =AK34/AK33 | AL35: =AL34/AL33 | AM35: =AM34/AM33 | AP35: =AP34/AP33 | AQ35: =AQ34/AQ33 | AR35: =AR34/AR33 | AT35: =AT34/AT33 | AU35: =AU34/AU33 | AX35: =AX34/AX33 | AY35: =AY34/AY33 | AZ35: =AZ34/AZ33 | BB35: =BB34/BB33 | BC35: =BC34/BC33
B36: Investment yield (annual) | C36: 0.064209551 | D36: 0.071 | E36: 0.074 | F36: 0.072 | H36: 0.075 | J36: =1.85*4 | K36: 0.073 | M36: =1.79*4% | P36: 0.06510227 | Q36: 0.073158725 | R36: 0.074141788 | S36: 0.058 | U36: 0.081 | W36: 0.072 | Z36: -0.046 | AC36: 0.064429019 | AD36: 0.069027271 | AE36: 0.070574598 | AF36: 0.073 | AH36: 0.0784 | AJ36: =AF36 | AK36: 0.076 | AM36: =AF36 | AP36: 0.059461319 | AQ36: 0.067305808 | AR36: 0.076921224 | AX36: 0.067483017 | AY36: 0.068953064 | AZ36: 0.076036403
B39: Key observations / commentary
A40: -> | B40: Growth observtions are covered in the previous tab
A41: -> | B41: FY25 claims ratio for Niva is 61.2% compared to 64.5% of Care and 70.3% of Star; Both Care and Star have seen a significant YoY increase in its claims ratio but Niva has seen a moderate increase only
A42: -> | B42: Star has already met the EOM guidelines; Care is on track to meet this in FY25 itself; However, Niva expects to achive this from FY26 onwards
A43: -> | B43: Combined ratio deteriorated for all SAHI in FY25 due to elevated claims ratio; Niva has been able to match the combined ratio with Care and star, in spite of having higher EOM, due to lower relative claims
A44: -> | B44: Star and Niva are comfortable with solvency margins; Care is close to the regulatory requirement so it might need to raise capital in next 12 months or slow down its growth - > good for other SAHIs
A45: -> | B45: Star is most aggressive wrt investment book as their yields are the highest; however they have mainted their leverage at comfortable levels (which can also be seen by high insolvency); Care and Niva are similar wrt investment yields but Care is more levered
A46: -> | B46: Care's profitability has taken a deep hit in FY25 and the company made only 6.9% ROE compared to 15.5% in the last year
A47: -> | B47: In summary, Star is slowest to grow on topline but consistently making mid-teen ROE; Care and Niva are growing their topline but with no / choppy profitability

Sheet Management commentary 
A2: xx | B2: Q4'26 Concall | C2: Niva Bupa | D2: Star Health | E2: ICICI Lombard | F2: Go Digit
B3: Growth | C3: FY26 GWP ₹9,433 Cr (+27.4%); Q4 GWP ₹2,880 Cr (+39% YoY); Retail market share 10.4% Q4 (up from 9%); Net add 58k agents in FY26 | D3: FY26 GWP ₹20,369 Cr (+16%); Q4 +17%; Fresh retail +38% Q4; NTI mix improved to 93% (vs 89% FY25); Policy count +8% YoY | E3: FY26 GDPI +7% (vs industry +9.2%); Q4 +18.2%; Retail Health +51.1% FY26 (share 4.1%, up from 3.3%); Motor H2 +12%; Health +20% FY26 | F3: FY26 GWP ~₹11,300 Cr (+16.2%); Q4 GDPI +21.3%; Q4 GWP optically +6.2% (suppressed by ₹252 Cr reinsurance exit; ex-health +18.8%); 2-wheeler Q4 +52%
B4: Profitability | C4: IFRS PAT ₹366 Cr (+80% FY); Q4 PAT +90% YoY; FY COR 101.4% (↓160bps); Q4 COR 97.4%; EOM 33.7%; ROE 10.7%; Solvency 2.49x | D4: FY26 PAT ₹911 Cr (+16%); Underwriting profit ₹206 Cr (vs loss ₹165 Cr); FY COR 98.8%; Q4 reported PAT loss ₹55 Cr (equity MTM ₹558 Cr); Normalised PAT ₹1,222 Cr (+45%); Normalised ROE 13.1% | E4: FY26 PAT ₹2,761 Cr (+14.1%); FY COR 102.4%; Q4 COR 100.5% (best quarterly in recent history); ROAE 17.8%; Solvency 2.67x; Dividend ₹13.50/share | F4: Q4 PAT ₹179 Cr (+69%); FY26 ROE 17.7% (on IGAAP net worth); FY26 COR 105.7% (↓1.2pp); DAC pre-tax ₹2,470 Cr (~65% unwinds FY27); Solvency 2.42x
B5: Competition | C5: Channel mix: Agency 30%, Brokers 30%, Banks 20%; New:Renewal ~40:60; Long-term policies ~20% of book; PPN 49 cities, 1,000+ hospitals | D5: Agency >90% of retail; 8 lakh+ agents (target 1M in 2 yrs); agent productivity +37% fresh; SME now 78% of group (vs 58% FY25); Long-term policies 51% of fresh GWP | E5: Retail Health share 4.1% FY26 (up from 3.3%); long-term 42.1% of fresh NB (vs 28.5%); Motor retention +5%; IL OneForce 10k+ sales users; fire: deliberate market share sacrifice on pricing discipline | F5: Opex 7% of GWP (best-in-class vs peers >9.5%); specialty commercial lines new growth vector — target ₹1,000 Cr in 3-5 years; motor pricing correction visible April; CV at historic low (24% vs ~40% FY20)
B6: Regulations | C6: Ind AS (IFRS 17) effective Apr 2026 – reporting-ready; EOM 33.7% (vs 36% limit); Banca regulation risk largely de-risked via retail cross-sell focus | D6: IFRS mandatory Apr 2026 – company already aligned; EOM compliant; PIR (Public Insurance Registry) positive for underwriting data quality | E6: IFRS mandatory Apr 2026; seeking Year-1 forbearance; IFRS adoption to reduce reported COR by 300-450bps; Motor TP hike overdue (~5 yrs); EOM: only 21/34 players compliant | F6: First insurer with full-year Ind AS audited results; Ind AS net worth ₹7,600 Cr vs IGAAP ₹4,600 Cr (₹3,000 Cr excess); EOM breach due to 2W mix (not opex); acquisition cost intervention expected within 2-3 months
B7: Others / Highlights | C7: NPS 60; Claims 94%+; COR target 99% by FY29; ROE mid-to-high teens by FY29 | D7: Renewal ratio 99% (+2pp); NPS 62; Repriced ~80% of book; Annual price increase planned across all products; Medical inflation 12-13% | E7: IL TakeCare FY26 GWP ₹517 Cr (vs ₹224 Cr FY25); Motor loss ratio 66.3% (within 65-67% guidance); Call Centre NPS 74 (Q4) | F7: AUM ₹23,000 Cr (+16.3%); Equity allocation 8.5% (target 10%); FY27 reinsurance renewed – fire/engineering capacity up, NatCat limit ₹1,600→₹2,000 Cr
A10: xx | B10: Q3'26 Concall | C10: Niva Bupa | D10: Star Health | E10: ICICI Lombard | F10: Go Digit
B11: Growth | C11: Q3 GWP +31% YoY; 9M GWP +26%; Retail +33% (9M), +46% fresh (Q3); Market share 10.2% Q3; Agency +43%; Digital D2C +70% | D11: Q3 GWP +23%; 9M GWP +16%; Fresh retail +45% Q3; Retail market share 31.3% (9M); Long-term policies 51% of fresh GWP | E11: Q3 GDPI ₹7,041 Cr (+13.3% vs industry +11.5%); 9M underperformed (+3.6% vs industry +8.7%); Retail Health +85.8% Q3 (share 4.5%); Health +42% Q3 | F11: Q3 GDPI ₹2,557 Cr (+20.9%); GWP like-like +18.5% (headline +8.7% suppressed by ₹254 Cr govt health exit); 2-wheeler +47% Q3
B12: Profitability | C12: 9M IFRS PAT ₹208 Cr (+74%); Q3 PAT ₹77 Cr (incl. ₹20 Cr one-off wage code); 9M COR 102.9% (↓50bps); Retail loss ratio 66.9%; Solvency 2.49x | D12: Q3 PAT ₹449 Cr (vs ₹87 Cr); 9M PAT ₹966 Cr (+87%); Q3 COR 98.9% (↓320bps); 9M COR 99.8%; 9M underwriting profit ₹20 Cr (vs loss ₹227 Cr) | E12: Q3 PAT ₹680 Cr (n-basis, flat YoY); wage code one-time ₹55 Cr hit; ex-wage code Q3 COR 102.2%; 9M PAT ₹2,225 Cr (+11.3%); ROE 19.5% (9M); Solvency 2.69x | F12: Q3 PAT ₹140 Cr (+37%); 9M profit already exceeded full-year FY25; IFRS COR 105% (↓1.2pp); Motor OD loss ratio elevated at 75.6%; corrective pricing taken Oct & Jan
B13: Competition | C13: GST-driven volume acceleration sustaining; ReAssure 3.0 fastest growing (inflation-proof, unlimited SI); PPN 1,100 hospitals in 47 cities | D13: 8 lakh+ agents; Corporate SME now 73% of group (vs 44% LY); Group loss ratio improved 94.6%→83.5% (9M); 66% fresh from semi-urban/rural | E13: Motor market share #1 at 10.7% (9M); Retail Health share 4.5% Q3 (up from 3.2%); Motor COR 106.9% vs industry 128.5%; Commercial: SME fire growing, large fire underwriting disciplined | F13: Motor 66% of mix; opex 7% of GWP (best-in-class); EV 2-wheeler tail risk reinsurance taken; CV at all-time low 19%
B14: Regulations | C14: Insurance Amendment Act: 100% FDI key positive; IFRS transition ahead of Apr 2027; EOM compliant (ex-1/n basis); GST savings ~50bps COR benefit (offset by ITC loss) | D14: IFRS mandatory Apr 2027; Senior citizen trail commission cut to 10%; Common empanelment 1,000 hospitals live (target 5,000); Medical inflation 12-13% | E14: 100% FDI via Insurance Amendment Bill; Wage code ₹55 Cr one-time hit; GST exemption on retail health driving first-time buyers in tier 2/3; 1/n tracked on n-basis internally | F14: EOM breach due to 2W mix shift and govt health exit; would comply on segment-wise basis; advocating LOB-wise EOM to IRDAI; IFRS COR disclosed for first time
B15: Others / Highlights | C15: NPS 58; Claims ~95%; App MAU ~600k; Common empanelment – 7 infection protocols live | D15: Renewal persistency 99.2% (9M); NPS 64; App 13M downloads, 1.5M MAU; AI claims platform 57% traffic migrated | E15: Digital servicing 60% (vs 38% Apr'25); IL TakeCare 19.7M downloads, 9M GWP ₹354 Cr; Motor loss ratio 9M 66.3% (within guidance) | F15: AUM ₹22,509 Cr; Equity allocation 7.4% (doubled in 12-15 months); Unrealised gains ₹686 Cr; Promoter buyback at ₹375/share
A17: xx | B17: Q2'26 Concall | C17: Niva Bupa | D17: Star Health | E17: ICICI Lombard | F17: Go Digit
B18: Growth | C18: GWP +24.5% YoY (ex-1/n); Retail +18%; steady market share (~10%). | D18: GWP +12% YoY; Retail +17% (₹8,332 Cr); 98% renewal persistency; digital NB up. | E18: GDPI -1.9% YoY (core GDPI +3.5%); Retail Health +32%; Fire segment growth, Motor faces challenges. | F18: Net worth +35%; AUM ₹20,861 Cr; customer base 71m.
B19: Profitability | C19: IFRS PAT ₹62 Cr (vs ₹24 Cr); Combined ratio 103.1% (↓141bps); Claims settlement 95.2%. | D19: PAT ₹55 Cr (↓51% YoY); H1 PAT ₹518 Cr (+21% YoY); Loss ratio 71.8% (↓190bps); Combined ratio 101%. | E19: PAT ₹820 Cr (+18% YoY); Combined ratio 102.9%; Core segment margins up; ROE 20.5%. | F19: First positive PAT; Combined ratio ~107.5%. Net retention ~65%. IFRS ROE 4.8%.
B20: Competition | C20: Retail share stable (~68%); Strong surge in queries/conversions post-GST; ReAssure 3.0 launched. | D20: Continued retail leadership (32% market share), Super Star >₹1,250 Cr premium; strong digital app traction (12m downloads). | E20: Leadership in Motor (10.5% share); Retail Health share ↑3.5%; cautious commercial vehicle approach due to pricing. | F20: 2-wheeler focus (31% of motor premium); retail health <10%; tactical reinsurance in Fire.
B21: Regulations | C21: IFRS metrics used; GST cut to zero driving affordability; solvency 2.85x. | D21: IFRS transition ahead of Apr'27; GST impacts pricing and claims; solvency robust at 2.15x. | E21: GST cut fully passed to policyholders; solvency 2.7x. | F21: Full IFRS disclosure incl. DAC, reserve rate. Solvency 227%.
